Workbook

Sheet 统计表
A1: 指标 | B1: 类型1 | C1: 类型2 | D1: 2024全年 | E1: 2025全年 | F1: 2025 1-8月 | G1: 2026 1-8月 | H1: 2026vs2025波动原因
A2: 订单均价 | B2: 拼大团 | C2: 含大交通散拼团-大车 | D2: ='测算底稿'!B42 | E2: ='测算底稿'!C42 | F2: ='测算底稿'!D42 | G2: ='测算底稿'!E42 | H2: ="均价"&TEXT('测算底稿'!F42,"+0%;-0%;0%")&"（"&IF('测算底稿'!F42>0.03,"增长",IF('测算底稿'!F42<-0.03,"下降","基本持平"))&"）。"&"短线亚洲占比上升拉低均价（暑期首尔客流+30%、曼谷/吉隆坡/新加坡约+20%）；批发端价格竞争延续（2025年批发毛利率−1.04个百分点）"
C3: 当地拼团多日游-大车 | D3: ='测算底稿'!B43 | E3: ='测算底稿'!C43 | F3: ='测算底稿'!D43 | G3: ='测算底稿'!E43 | H3: ="均价"&TEXT('测算底稿'!F43,"+0%;-0%;0%")&"（"&IF('测算底稿'!F43>0.03,"增长",IF('测算底稿'!F43<-0.03,"下降","基本持平"))&"）。"&"目的地大巴团为标准化产品，未见公开调价"
C4: 一日游 | D4: ='测算底稿'!B44 | E4: ='测算底稿'!C44 | F4: ='测算底稿'!D44 | G4: ='测算底稿'!E44 | H4: ="均价"&TEXT('测算底稿'!F44,"+0%;-0%;0%")&"（"&IF('测算底稿'!F44>0.03,"增长",IF('测算底稿'!F44<-0.03,"下降","基本持平"))&"）。"&"标准化低价产品，价格刚性"
B5: 拼小团 | C5: 含大交通散拼团-小车 | D5: ='测算底稿'!B45 | E5: ='测算底稿'!C45 | F5: ='测算底稿'!D45 | G5: ='测算底稿'!E45 | H5: ="均价"&TEXT('测算底稿'!F45,"+0%;-0%;0%")&"（"&IF('测算底稿'!F45>0.03,"增长",IF('测算底稿'!F45<-0.03,"下降","基本持平"))&"）。"&"小团供给增加（众信主推2–16人欧洲精品小团），同业跟进加剧竞争"
C6: 当地拼团-小车 | D6: ='测算底稿'!B46 | E6: ='测算底稿'!C46 | F6: ='测算底稿'!D46 | G6: ='测算底稿'!E46 | H6: ="均价"&TEXT('测算底稿'!F46,"+0%;-0%;0%")&"（"&IF('测算底稿'!F46>0.03,"增长",IF('测算底稿'!F46<-0.03,"下降","基本持平"))&"）。"&"目的地小团定价稳定"
B7: 私家团 | C7: 含大交通私家团 | D7: ='测算底稿'!B47 | E7: ='测算底稿'!C47 | F7: ='测算底稿'!D47 | G7: ='测算底稿'!E47 | H7: ="均价"&TEXT('测算底稿'!F47,"+0%;-0%;0%")&"（"&IF('测算底稿'!F47>0.03,"增长",IF('测算底稿'!F47<-0.03,"下降","基本持平"))&"）。"&"私家团向日本、东南亚等短线家庭出游扩展，结构性拉低均价"
C8: 当地私家团 | D8: ='测算底稿'!B48 | E8: ='测算底稿'!C48 | F8: ='测算底稿'!D48 | G8: ='测算底稿'!E48 | H8: ="均价"&TEXT('测算底稿'!F48,"+0%;-0%;0%")&"（"&IF('测算底稿'!F48>0.03,"增长",IF('测算底稿'!F48<-0.03,"下降","基本持平"))&"）。"&"目的地私家团定价稳定"
B9: 定制游 | C9: 含大交通定制 | D9: ='测算底稿'!B49 | E9: ='测算底稿'!C49 | F9: ='测算底稿'!D49 | G9: ='测算底稿'!E49 | H9: ="均价"&TEXT('测算底稿'!F49,"+0%;-0%;0%")&"（"&IF('测算底稿'!F49>0.03,"增长",IF('测算底稿'!F49<-0.03,"下降","基本持平"))&"）。"&"高端定制客群价格敏感度低"
C10: 当地定制 | D10: ='测算底稿'!B50 | E10: ='测算底稿'!C50 | F10: ='测算底稿'!D50 | G10: ='测算底稿'!E50 | H10: ="均价"&TEXT('测算底稿'!F50,"+0%;-0%;0%")&"（"&IF('测算底稿'!F50>0.03,"增长",IF('测算底稿'!F50<-0.03,"下降","基本持平"))&"）。"&"目的地定制定价稳定"
A11: 收客人次 | B11: 拼大团 | C11: 含大交通散拼团-大车 | D11: ='测算底稿'!B53 | E11: ='测算底稿'!C53 | F11: ='测算底稿'!D53 | G11: ='测算底稿'!E53 | H11: ="人次"&TEXT('测算底稿'!F53,"+0%;-0%;0%")&"（"&IF('测算底稿'!F53>0.03,"增长",IF('测算底稿'!F53<-0.03,"下降","基本持平"))&"）。"&"公司主动缩减获客成本高、资金占用高的批发线路，2026H1旅游批发收入−10.20%；跟团需求向小团、私家团迁移"
C12: 当地拼团多日游-大车 | D12: ='测算底稿'!B54 | E12: ='测算底稿'!C54 | F12: ='测算底稿'!D54 | G12: ='测算底稿'!E54 | H12: ="人次"&TEXT('测算底稿'!F54,"+0%;-0%;0%")&"（"&IF('测算底稿'!F54>0.03,"增长",IF('测算底稿'!F54<-0.03,"下降","基本持平"))&"）。"&"随九类产品总客量回落（约−4%）；目的地参团需求本身稳定"
C13: 一日游 | D13: ='测算底稿'!B55 | E13: ='测算底稿'!C55 | F13: ='测算底稿'!D55 | G13: ='测算底稿'!E55 | H13: ="人次"&TEXT('测算底稿'!F55,"+0%;-0%;0%")&"（"&IF('测算底稿'!F55>0.03,"增长",IF('测算底稿'!F55<-0.03,"下降","基本持平"))&"）。"&"长线散客增加带动目的地一日游，抵消总客量回落"
B14: 拼小团 | C14: 含大交通散拼团-小车 | D14: ='测算底稿'!B56 | E14: ='测算底稿'!C56 | F14: ='测算底稿'!D56 | G14: ='测算底稿'!E56 | H14: ="人次"&TEXT('测算底稿'!F56,"+0%;-0%;0%")&"（"&IF('测算底稿'!F56>0.03,"增长",IF('测算底稿'!F56<-0.03,"下降","基本持平"))&"）。"&"大团变小团趋势延续，公司资源转向高附加值产品；2026H1旅游零售收入+20.66%"
C15: 当地拼团多日游-小车 | D15: ='测算底稿'!B57 | E15: ='测算底稿'!C57 | F15: ='测算底稿'!D57 | G15: ='测算底稿'!E57 | H15: ="人次"&TEXT('测算底稿'!F57,"+0%;-0%;0%")&"（"&IF('测算底稿'!F57>0.03,"增长",IF('测算底稿'!F57<-0.03,"下降","基本持平"))&"）。"&"小团化趋势延续"
B16: 私家团 | C16: 含大交通私家团 | D16: ='测算底稿'!B58 | E16: ='测算底稿'!C58 | F16: ='测算底稿'!D58 | G16: ='测算底稿'!E58 | H16: ="人次"&TEXT('测算底稿'!F58,"+0%;-0%;0%")&"（"&IF('测算底稿'!F58>0.03,"增长",IF('测算底稿'!F58<-0.03,"下降","基本持平"))&"）。"&"家庭亲子出游偏好私密成团；零售门店与加盟扩张带动"
C17: 当地私家团 | D17: ='测算底稿'!B59 | E17: ='测算底稿'!C59 | F17: ='测算底稿'!D59 | G17: ='测算底稿'!E59 | H17: ="人次"&TEXT('测算底稿'!F59,"+0%;-0%;0%")&"（"&IF('测算底稿'!F59>0.03,"增长",IF('测算底稿'!F59<-0.03,"下降","基本持平"))&"）。"&"家庭出游私密化，同上"
B18: 定制游 | C18: 含大交通定制 | D18: ='测算底稿'!B60 | E18: ='测算底稿'!C60 | F18: ='测算底稿'!D60 | G18: ='测算底稿'!E60 | H18: ="人次"&TEXT('测算底稿'!F60,"+0%;-0%;0%")&"（"&IF('测算底稿'!F60>0.03,"增长",IF('测算底稿'!F60<-0.03,"下降","基本持平"))&"）。"&"定制需求扩张（2025年国内定制旅行市场规模超1,200亿元、同比+14%）"
C19: 当地定制 | D19: ='测算底稿'!B61 | E19: ='测算底稿'!C61 | F19: ='测算底稿'!D61 | G19: ='测算底稿'!E61 | H19: ="人次"&TEXT('测算底稿'!F61,"+0%;-0%;0%")&"（"&IF('测算底稿'!F61>0.03,"增长",IF('测算底稿'!F61<-0.03,"下降","基本持平"))&"）。"&"定制需求扩张，基数小"
A21: 单位：订单均价为元/单（每单终端成交价），收客人次为人次；2026vs2025 按1–8月同期比较。填写口径、依据与人均价附表见「口径说明」页。

Sheet 测算底稿
A1: 众信旅游(002707.SZ) 调研表测算底稿
A2: 蓝字=公开披露输入｜黑字=公式｜黄底=分析假设（可改，统计表自动联动）｜金额单位：亿元，价格：元，人次：人次
A4: A. 公开锚点（营业收入，亿元） | B4: 2024全年 | C4: 2025全年 | D4: 2025H1 | E4: 2026H1 | F4: 2025同比 | G4: 2026H1同比 | J4: 来源
A5: 旅游批发 | B5: =C5/(1+F5) | C5: 50.28 | D5: =E5/(1+G5) | E5: 19.79 | F5: 0.049 | G5: -0.102 | J5: 2025年报（2026-04-27）及中期报告（2026-08-28），经中新经纬、腾讯新闻等转述；2024全年与2025H1按披露同比反推
A6: 旅游零售 | B6: =C6/(1+F6) | C6: 9.26 | D6: =E6/(1+G6) | E6: 4.77 | F6: 0.2413 | G6: 0.2066 | J6: 同上
A7: 整合营销服务 | B7: =C7/(1+F7) | C7: 8.4 | D7: =E7/(1+G7) | E7: 3.32 | F7: -0.0348 | G7: 0.28 | J7: 同上
A8: 营业总收入 | B8: =C8/(1+F8) | C8: 68.22 | D8: =E8/(1+G8) | E8: 27.99 | F8: 0.0569 | G8: -0.026 | J8: 同上
A9: 其他收入（总收入−三项合计） | B9: =B8-SUM(B5:B7) | C9: =C8-SUM(C5:C7) | D9: =D8-SUM(D5:D7) | E9: =E8-SUM(E5:E7) | J9: 三项分业务加总与总收入的差额，为未单列的其他业务收入，非口径矛盾
A10: 2025 总服务人次（人次） | C10: 1680000 | J10: 众信旅游集团2025年大数据报告（2025-12-31）：总服务人次突破168万；口径含签证、单项、入境、会奖等全部服务
A11: 其中：众信博睿会奖服务（人次） | C11: 240746 | J11: 同上大数据报告
A13: B. 口径假设 | B13: 取值 | J13: 依据
A14: 批发渠道佣金率（批发收入为同行价→还原终端成交价） | B14: 0.08 | J14: 出境游批发给零售同行的常见返佣区间约5%–10%，取中值
A15: 九类团队产品占休闲终端成交额比例 | B15: 0.85 | J15: 批发+零售收入还含自由行套餐、邮轮、游学、签证、机票等单项，按15%剔除
A16: 7–8月占全年休闲成交额比例 | B16: 0.26 | J16: 2025年上半年占全年约44%；7–8月为暑期出境高峰（长线欧洲、亲子），取下半年约45%
A17: 2026年7–8月休闲成交额同比 | B17: -0.04 | J17: 2026H1休闲成交额约−5.8%；暑期全国出入境航线旅客+约3%、短线亚洲火热，部分对冲
A19: C. 休闲终端成交额（亿元） | B19: 2024全年 | C19: 2025全年 | D19: 2025 1-8月 | E19: 2026 1-8月 | J19: 说明
A20: 上半年终端成交额 | D20: =D5/(1-$B$14)+D6 | E20: =E5/(1-$B$14)+E6 | J20: 批发÷(1−佣金率)+零售；整合营销（会奖）不在九类产品内，已剔除
A21: 7–8月终端成交额 | D21: =C22*$B$16 | E21: =D21*(1+$B$17)
A22: 全年/1–8月 休闲终端成交额 | B22: =B5/(1-$B$14)+B6 | C22: =C5/(1-$B$14)+C6 | D22: =D20+D21 | E22: =E20+E21
A23: 其中九类团队产品成交额 | B23: =B22*$B$15 | C23: =C22*$B$15 | D23: =D22*$B$15 | E23: =E22*$B$15
A25: D. 九类产品假设 | B25: 单均人数（人/单） | C25: 人次占比 2024 | D25: 人次占比 2025 | E25: 人次占比 2026 1-8月 | F25: 人均价 2024（元） | G25: 人均价 2025（元） | H25: 人均价 2026 1-8月（元） | J25: 依据
A26: 含大交通散拼团-大车 | B26: 2 | C26: =1-SUM(C27:C34) | D26: =1-SUM(D27:D34) | E26: =1-SUM(E27:E34) | F26: 10300 | G26: 9800 | H26: 9500 | J26: 占比=1−其余八类（残差）。人均：长线约2.2万（众信欧洲13天北京出发2.48万起、自营线3.88万起）×约25%＋短线约5,800（日本6天6,580起、东南亚/韩国更低）×约75%
A27: 当地拼团多日游-大车 | B27: 2.2 | C27: 0.08 | D27: 0.08 | E27: 0.08 | F27: 3000 | G27: 3000 | H27: 2950 | J27: 途风旅游网美加/欧洲目的地大巴团；携程口径目的地参团人均2,000–3,000元
A28: 一日游 | B28: 2.3 | C28: 0.13 | D28: 0.13 | E28: 0.135 | F28: 620 | G28: 600 | H28: 600 | J28: 目的地一日游，标准化产品
A29: 含大交通散拼团-小车 | B29: 2.2 | C29: 0.05 | D29: 0.07 | E29: 0.09 | F29: 14500 | G29: 14000 | H29: 13800 | J29: 精品小团团费通常高于常规跟团约两成，且集中在欧洲等长线；众信主推2–16人欧洲精品小团、Mini Tour/U-love
A30: 当地拼团-小车 | B30: 2.4 | C30: 0.025 | D30: 0.03 | E30: 0.035 | F30: 4000 | G30: 4000 | H30: 4000 | J30: 途风12人以内目的地小团
A31: 含大交通私家团 | B31: 3.2 | C31: 0.035 | D31: 0.045 | E31: 0.055 | F31: 15500 | G31: 15000 | H31: 14800 | J31: 私家团以家庭为单位成团；携程口径出发地参团私家团人均>5,000元（含国内），出境长短线加权更高
A32: 当地私家团 | B32: 3.4 | C32: 0.02 | D32: 0.025 | E32: 0.03 | F32: 3500 | G32: 3500 | H32: 3500 | J32: 携程口径私家团人均>3,500元
A33: 含大交通定制 | B33: 3 | C33: 0.012 | D33: 0.015 | E33: 0.018 | F33: 26000 | G33: 25000 | H33: 25000 | J33: 定制游客单价约为跟团游2–3倍；优定制以长线高端为主，累计服务5万+人次
A34: 当地定制 | B34: 3 | C34: 0.003 | D34: 0.005 | E34: 0.007 | F34: 8000 | G34: 8000 | H34: 8000 | J34: 目的地定制包车/管家服务
A35: 合计（校验=100%） | C35: =SUM(C26:C34) | D35: =SUM(D26:D34) | E35: =SUM(E26:E34)
A37: E. 产出 | B37: 2024全年 | C37: 2025全年 | D37: 2025 1-8月 | E37: 2026 1-8月 | F37: 2026vs2025 1-8月 | J37: 说明
A38: 加权人均价（元/人） | B38: =SUMPRODUCT(C26:C34,F26:F34) | C38: =SUMPRODUCT(D26:D34,G26:G34) | D38: =SUMPRODUCT(D26:D34,G26:G34) | E38: =SUMPRODUCT(E26:E34,H26:H34) | F38: =E38/D38-1
A39: 九类产品总收客人次 | B39: =B23*100000000/B38 | C39: =C23*100000000/C38 | D39: =D23*100000000/D38 | E39: =E23*100000000/E38 | F39: =E39/D39-1 | J39: ＝九类产品成交额÷加权人均价
A41: 订单均价（元/单）
A42: 含大交通散拼团-大车 | B42: =ROUND(F26*$B26,0) | C42: =ROUND(G26*$B26,0) | D42: =ROUND(G26*$B26,0) | E42: =ROUND(H26*$B26,0) | F42: =E42/D42-1
A43: 当地拼团多日游-大车 | B43: =ROUND(F27*$B27,0) | C43: =ROUND(G27*$B27,0) | D43: =ROUND(G27*$B27,0) | E43: =ROUND(H27*$B27,0) | F43: =E43/D43-1
A44: 一日游 | B44: =ROUND(F28*$B28,0) | C44: =ROUND(G28*$B28,0) | D44: =ROUND(G28*$B28,0) | E44: =ROUND(H28*$B28,0) | F44: =E44/D44-1
A45: 含大交通散拼团-小车 | B45: =ROUND(F29*$B29,0) | C45: =ROUND(G29*$B29,0) | D45: =ROUND(G29*$B29,0) | E45: =ROUND(H29*$B29,0) | F45: =E45/D45-1
A46: 当地拼团-小车 | B46: =ROUND(F30*$B30,0) | C46: =ROUND(G30*$B30,0) | D46: =ROUND(G30*$B30,0) | E46: =ROUND(H30*$B30,0) | F46: =E46/D46-1
...

Sheet 口径说明
A1: 众信旅游（002707.SZ）调研表 · 填写口径与依据
A3: 一、口径
A4: 订单均价 | B4: 每单终端成交价（元/单）。一单平均2.0–3.4人（拼团约2人，私家团/定制约3人）。若贵方口径为「人均价」，见第四部分附表。
A5: 收客人次 | B5: 九类团队产品的出游人次。不含会奖（众信博睿）、签证、机票等单项服务及入境接待。
A6: 波动原因 | B6: 比较口径为2026年1–8月对2025年1–8月；方向词按涨跌幅自动生成（>+3%增长、<−3%下降、其余基本持平）。
A7: 产品名称 | B7: 表中「当地拼团-小车」（均价行）与「当地拼团多日游-小车」（人次行）按同一类产品处理。
A8: 二、数据性质与可信度
A9: 数据性质 | B9: 众信未按九类产品披露均价与人次，也不披露月度数据。本表由公开财报收入、公司公布的服务人次、众信旗下悠哉网/途风的公开标价及行业价格带推算。
A10: 订单均价 | B10: 中等可信：锚定众信公开标价（欧洲13天北京出发2.48万元起、自营线3.88万元起，日本6天6,580元起）与行业价格带。
A11: 收客人次 | B11: 较低可信。最大不确定来源：按收入反推，2025年九类团队产品约64万人次，仅占公司口径总服务人次（168万）扣除会奖（24.07万）后的约45%，差额应为签证、机票、保险等单项服务，公司未拆分。
A13: 三、公开锚点（营业收入，亿元）
A14: 业务 | B14: 2024全年 | C14: 2025全年 | D14: 2025上半年 | E14: 2026上半年 | F14: 来源
A15: 旅游批发 | B15: ='测算底稿'!B5 | C15: ='测算底稿'!C5 | D15: ='测算底稿'!D5 | E15: ='测算底稿'!E5 | F15: 2025年报、2026中报（经中新经纬、腾讯新闻等转述）；2024与2025上半年按披露同比反推
A16: 旅游零售 | B16: ='测算底稿'!B6 | C16: ='测算底稿'!C6 | D16: ='测算底稿'!D6 | E16: ='测算底稿'!E6 | F16: 同上
A17: 整合营销服务 | B17: ='测算底稿'!B7 | C17: ='测算底稿'!C7 | D17: ='测算底稿'!D7 | E17: ='测算底稿'!E7 | F17: 同上
A18: 营业总收入 | B18: ='测算底稿'!B8 | C18: ='测算底稿'!C8 | D18: ='测算底稿'!D8 | E18: ='测算底稿'!E8 | F18: 同上
A19: 其他（总收入−三项合计） | B19: ='测算底稿'!B9 | C19: ='测算底稿'!C9 | D19: ='测算底稿'!D9 | E19: ='测算底稿'!E9 | F19: 分业务合计与总收入的差额，为未单列的其他收入，非口径矛盾
A20: 2025总服务人次 | C20: ='测算底稿'!C10 | F20: 众信旅游集团2025年大数据报告（2025-12-31），含会奖24.07万人次
A22: 四、附表：人均价（元/人）
A23: 产品 | B23: 2024全年 | C23: 2025全年 | D23: 2025 1-8月 | E23: 2026 1-8月 | F23: 单均人数（人/单）
A24: 含大交通散拼团-大车 | B24: ='测算底稿'!F26 | C24: ='测算底稿'!G26 | D24: ='测算底稿'!G26 | E24: ='测算底稿'!H26 | F24: ='测算底稿'!B26
A25: 当地拼团多日游-大车 | B25: ='测算底稿'!F27 | C25: ='测算底稿'!G27 | D25: ='测算底稿'!G27 | E25: ='测算底稿'!H27 | F25: ='测算底稿'!B27
A26: 一日游 | B26: ='测算底稿'!F28 | C26: ='测算底稿'!G28 | D26: ='测算底稿'!G28 | E26: ='测算底稿'!H28 | F26: ='测算底稿'!B28
A27: 含大交通散拼团-小车 | B27: ='测算底稿'!F29 | C27: ='测算底稿'!G29 | D27: ='测算底稿'!G29 | E27: ='测算底稿'!H29 | F27: ='测算底稿'!B29
A28: 当地拼团-小车 | B28: ='测算底稿'!F30 | C28: ='测算底稿'!G30 | D28: ='测算底稿'!G30 | E28: ='测算底稿'!H30 | F28: ='测算底稿'!B30
A29: 含大交通私家团 | B29: ='测算底稿'!F31 | C29: ='测算底稿'!G31 | D29: ='测算底稿'!G31 | E29: ='测算底稿'!H31 | F29: ='测算底稿'!B31
A30: 当地私家团 | B30: ='测算底稿'!F32 | C30: ='测算底稿'!G32 | D30: ='测算底稿'!G32 | E30: ='测算底稿'!H32 | F30: ='测算底稿'!B32
A31: 含大交通定制 | B31: ='测算底稿'!F33 | C31: ='测算底稿'!G33 | D31: ='测算底稿'!G33 | E31: ='测算底稿'!H33 | F31: ='测算底稿'!B33
A32: 当地定制 | B32: ='测算底稿'!F34 | C32: ='测算底稿'!G34 | D32: ='测算底稿'!G34 | E32: ='测算底稿'!H34 | F32: ='测算底稿'!B34
A34: 五、关键假设
A35: 批发渠道佣金率 | B35: ='测算底稿'!B14 | C35: 批发收入为给同行的同行价，按此还原终端成交价
A36: 九类产品占休闲成交额 | B36: ='测算底稿'!B15 | C36: 剔除自由行套餐、邮轮、游学、签证、机票等
A37: 7–8月占全年成交额 | B37: ='测算底稿'!B16 | C37: 暑期出境高峰；2025上半年占全年约44%
A38: 2026年7–8月成交额同比 | B38: ='测算底稿'!B17 | C38: 2026上半年约−5.8%，暑期出入境航线旅客+约3%部分对冲
A39: 产品结构 | B39: ="2024→2026逐年向小团、私家团、定制迁移；含大交通大团人次占比 "&TEXT('测算底稿'!C26,"0%")&" → "&TEXT('测算底稿'!D26,"0%")&" → "&TEXT('测算底稿'!E26,"0%")&"（2024全年 → 2025全年 → 2026年1–8月）。"
A41: 六、建议访谈核实（最能提升本表精度的四个数）
A42: · | B42: 2025年九类团队产品合计出游人次（或168万服务人次的构成）——决定全部人次格的量级
A43: · | B43: 批发与零售各自的产品结构：大团 / 小团 / 私家团 / 定制的人次占比
A44: · | B44: 7–8月收客占全年比例——决定两列1–8月数据
A45: · | B45: 途风（目的地参团）业务规模及一日游占比
