Workbook

Sheet 统计表
A1: 指标 | B1: 类型1 | C1: 类型2 | D1: 2024全年 | E1: 2025全年 | F1: 2025 1-8月 | G1: 2026 1-8月 | H1: 2026vs2025波动原因
A2: 订单均价 | B2: 拼大团 | C2: 含大交通散拼团-大车 | D2: ='测算底稿'!B43 | E2: ='测算底稿'!C43 | F2: ='测算底稿'!D43 | G2: ='测算底稿'!E43 | H2: ="均价"&TEXT('测算底稿'!F43,"+0.0%;-0.0%;0.0%")&"（"&IF('测算底稿'!F43>0.03,"增长",IF('测算底稿'!F43<-0.03,"下降","基本持平"))&"）。"&"人均花费下行（全国2026H1人均出游花费−3.2%）；新开华中/华北门店以高铁可达的中短线为主，拉低均价"
C3: 当地拼团多日游-大车 | D3: ='测算底稿'!B44 | E3: ='测算底稿'!C44 | F3: ='测算底稿'!D44 | G3: ='测算底稿'!E44 | H3: ="均价"&TEXT('测算底稿'!F44,"+0.0%;-0.0%;0.0%")&"（"&IF('测算底稿'!F44>0.03,"增长",IF('测算底稿'!F44<-0.03,"下降","基本持平"))&"）。"&"目的地大巴团价格竞争充分，随全国人均花费小幅下行"
C4: 一日游 | D4: ='测算底稿'!B45 | E4: ='测算底稿'!C45 | F4: ='测算底稿'!D45 | G4: ='测算底稿'!E45 | H4: ="均价"&TEXT('测算底稿'!F45,"+0.0%;-0.0%;0.0%")&"（"&IF('测算底稿'!F45>0.03,"增长",IF('测算底稿'!F45<-0.03,"下降","基本持平"))&"）。"&"标准化低价产品，价格刚性"
B5: 拼小团 | C5: 含大交通散拼团-小车 | D5: ='测算底稿'!B46 | E5: ='测算底稿'!C46 | F5: ='测算底稿'!D46 | G5: ='测算底稿'!E46 | H5: ="均价"&TEXT('测算底稿'!F46,"+0.0%;-0.0%;0.0%")&"（"&IF('测算底稿'!F46>0.03,"增长",IF('测算底稿'!F46<-0.03,"下降","基本持平"))&"）。"&"小团供给增加、同业跟进，价格小幅让利"
C6: 当地拼团-小车 | D6: ='测算底稿'!B47 | E6: ='测算底稿'!C47 | F6: ='测算底稿'!D47 | G6: ='测算底稿'!E47 | H6: ="均价"&TEXT('测算底稿'!F47,"+0.0%;-0.0%;0.0%")&"（"&IF('测算底稿'!F47>0.03,"增长",IF('测算底稿'!F47<-0.03,"下降","基本持平"))&"）。"&"目的地小团定价随市场小幅下行"
B7: 私家团 | C7: 含大交通私家团 | D7: ='测算底稿'!B48 | E7: ='测算底稿'!C48 | F7: ='测算底稿'!D48 | G7: ='测算底稿'!E48 | H7: ="均价"&TEXT('测算底稿'!F48,"+0.0%;-0.0%;0.0%")&"（"&IF('测算底稿'!F48>0.03,"增长",IF('测算底稿'!F48<-0.03,"下降","基本持平"))&"）。"&"中长线私家团为主，价格随市场小幅下行"
C8: 当地私家团 | D8: ='测算底稿'!B49 | E8: ='测算底稿'!C49 | F8: ='测算底稿'!D49 | G8: ='测算底稿'!E49 | H8: ="均价"&TEXT('测算底稿'!F49,"+0.0%;-0.0%;0.0%")&"（"&IF('测算底稿'!F49>0.03,"增长",IF('测算底稿'!F49<-0.03,"下降","基本持平"))&"）。"&"目的地私家团定价稳定"
B9: 定制游 | C9: 含大交通定制 | D9: ='测算底稿'!B50 | E9: ='测算底稿'!C50 | F9: ='测算底稿'!D50 | G9: ='测算底稿'!E50 | H9: ="均价"&TEXT('测算底稿'!F50,"+0.0%;-0.0%;0.0%")&"（"&IF('测算底稿'!F50>0.03,"增长",IF('测算底稿'!F50<-0.03,"下降","基本持平"))&"）。"&"高端定制客群价格敏感度低"
C10: 当地定制 | D10: ='测算底稿'!B51 | E10: ='测算底稿'!C51 | F10: ='测算底稿'!D51 | G10: ='测算底稿'!E51 | H10: ="均价"&TEXT('测算底稿'!F51,"+0.0%;-0.0%;0.0%")&"（"&IF('测算底稿'!F51>0.03,"增长",IF('测算底稿'!F51<-0.03,"下降","基本持平"))&"）。"&"目的地定制定价稳定"
A11: 收客人次 | B11: 拼大团 | C11: 含大交通散拼团-大车 | D11: ='测算底稿'!B54 | E11: ='测算底稿'!C54 | F11: ='测算底稿'!D54 | G11: ='测算底稿'!E54 | H11: ="人次"&TEXT('测算底稿'!F54,"+0.0%;-0.0%;0.0%")&"（"&IF('测算底稿'!F54>0.03,"增长",IF('测算底稿'!F54<-0.03,"下降","基本持平"))&"）。"&"整体：国内游收客"&TEXT('测算底稿'!F40,"+0%;-0%")&"（零售与加盟门店向华中、华北、华东扩张，五一国内游出游人次+168%；国内业务基数小）。结构："&"新增出发地客源被向小团、私家团和目的地参团的分流抵消，大团人次占比由约38%降至约28%"
C12: 当地拼团多日游-大车 | D12: ='测算底稿'!B55 | E12: ='测算底稿'!C55 | F12: ='测算底稿'!D55 | G12: ='测算底稿'!E55 | H12: ="人次"&TEXT('测算底稿'!F55,"+0.0%;-0.0%;0.0%")&"（"&IF('测算底稿'!F55>0.03,"增长",IF('测算底稿'!F55<-0.03,"下降","基本持平"))&"）。"&"整体：国内游收客"&TEXT('测算底稿'!F40,"+0%;-0%")&"（零售与加盟门店向华中、华北、华东扩张，五一国内游出游人次+168%；国内业务基数小）。结构："&"新增门店客源偏好目的地参团；新疆、云南等“顶流”目的地热度延续"
C13: 一日游 | D13: ='测算底稿'!B56 | E13: ='测算底稿'!C56 | F13: ='测算底稿'!D56 | G13: ='测算底稿'!E56 | H13: ="人次"&TEXT('测算底稿'!F56,"+0.0%;-0.0%;0.0%")&"（"&IF('测算底稿'!F56>0.03,"增长",IF('测算底稿'!F56<-0.03,"下降","基本持平"))&"）。"&"整体：国内游收客"&TEXT('测算底稿'!F40,"+0%;-0%")&"（零售与加盟门店向华中、华北、华东扩张，五一国内游出游人次+168%；国内业务基数小）。结构："&"目的地参团与短线客群增加带动一日游"
B14: 拼小团 | C14: 含大交通散拼团-小车 | D14: ='测算底稿'!B57 | E14: ='测算底稿'!C57 | F14: ='测算底稿'!D57 | G14: ='测算底稿'!E57 | H14: ="人次"&TEXT('测算底稿'!F57,"+0.0%;-0.0%;0.0%")&"（"&IF('测算底稿'!F57>0.03,"增长",IF('测算底稿'!F57<-0.03,"下降","基本持平"))&"）。"&"整体：国内游收客"&TEXT('测算底稿'!F40,"+0%;-0%")&"（零售与加盟门店向华中、华北、华东扩张，五一国内游出游人次+168%；国内业务基数小）。结构："&"大团变小团趋势延续；五一喀纳斯、伊犁等小团线路供不应求"
C15: 当地拼团多日游-小车 | D15: ='测算底稿'!B58 | E15: ='测算底稿'!C58 | F15: ='测算底稿'!D58 | G15: ='测算底稿'!E58 | H15: ="人次"&TEXT('测算底稿'!F58,"+0.0%;-0.0%;0.0%")&"（"&IF('测算底稿'!F58>0.03,"增长",IF('测算底稿'!F58<-0.03,"下降","基本持平"))&"）。"&"整体：国内游收客"&TEXT('测算底稿'!F40,"+0%;-0%")&"（零售与加盟门店向华中、华北、华东扩张，五一国内游出游人次+168%；国内业务基数小）。结构："&"新疆、云南、西北小车拼团成为主流形态"
B16: 私家团 | C16: 含大交通私家团 | D16: ='测算底稿'!B59 | E16: ='测算底稿'!C59 | F16: ='测算底稿'!D59 | G16: ='测算底稿'!E59 | H16: ="人次"&TEXT('测算底稿'!F59,"+0.0%;-0.0%;0.0%")&"（"&IF('测算底稿'!F59>0.03,"增长",IF('测算底稿'!F59<-0.03,"下降","基本持平"))&"）。"&"整体：国内游收客"&TEXT('测算底稿'!F40,"+0%;-0%")&"（零售与加盟门店向华中、华北、华东扩张，五一国内游出游人次+168%；国内业务基数小）。结构："&"家庭亲子出游偏好私密成团（2026暑期行业小团、私家团、定制预订占比稳步提升）"
C17: 当地私家团 | D17: ='测算底稿'!B60 | E17: ='测算底稿'!C60 | F17: ='测算底稿'!D60 | G17: ='测算底稿'!E60 | H17: ="人次"&TEXT('测算底稿'!F60,"+0.0%;-0.0%;0.0%")&"（"&IF('测算底稿'!F60>0.03,"增长",IF('测算底稿'!F60<-0.03,"下降","基本持平"))&"）。"&"整体：国内游收客"&TEXT('测算底稿'!F40,"+0%;-0%")&"（零售与加盟门店向华中、华北、华东扩张，五一国内游出游人次+168%；国内业务基数小）。结构："&"家庭出游私密化，目的地私家团与出发地私家团同步增长"
B18: 定制游 | C18: 含大交通定制 | D18: ='测算底稿'!B61 | E18: ='测算底稿'!C61 | F18: ='测算底稿'!D61 | G18: ='测算底稿'!E61 | H18: ="人次"&TEXT('测算底稿'!F61,"+0.0%;-0.0%;0.0%")&"（"&IF('测算底稿'!F61>0.03,"增长",IF('测算底稿'!F61<-0.03,"下降","基本持平"))&"）。"&"整体：国内游收客"&TEXT('测算底稿'!F40,"+0%;-0%")&"（零售与加盟门店向华中、华北、华东扩张，五一国内游出游人次+168%；国内业务基数小）。结构："&"定制需求扩张（2025年国内定制旅行市场规模超1,200亿元、同比+14%；2026暑期行业定制游预订人次同比超3倍）"
C19: 当地定制 | D19: ='测算底稿'!B62 | E19: ='测算底稿'!C62 | F19: ='测算底稿'!D62 | G19: ='测算底稿'!E62 | H19: ="人次"&TEXT('测算底稿'!F62,"+0.0%;-0.0%;0.0%")&"（"&IF('测算底稿'!F62>0.03,"增长",IF('测算底稿'!F62<-0.03,"下降","基本持平"))&"）。"&"整体：国内游收客"&TEXT('测算底稿'!F40,"+0%;-0%")&"（零售与加盟门店向华中、华北、华东扩张，五一国内游出游人次+168%；国内业务基数小）。结构："&"定制需求扩张，基数小"
A21: 口径：仅众信国内团队游（不含出境、入境、会奖）。单位：订单均价为元/单（每单终端成交价），收客人次为人次；2026vs2025 按1–8月同期比较。依据与人均价附表见「口径说明」页。

Sheet 测算底稿
A1: 众信旅游(002707.SZ) 国内游调研表测算底稿
A2: 蓝字=公开披露输入｜黑字=公式｜黄底=分析假设（可改，统计表自动联动）｜金额：亿元，价格：元，人次：人次
A4: A. 公开锚点（营业收入，亿元） | B4: 2024全年 | C4: 2025全年 | D4: 2025H1 | E4: 2026H1 | F4: 2025同比 | G4: 2026H1同比 | J4: 来源
A5: 旅游批发 | B5: =C5/(1+F5) | C5: 50.28 | D5: =E5/(1+G5) | E5: 19.79 | F5: 0.049 | G5: -0.102 | J5: 2025年报（2026-04-27）、2026中报（2026-08-28），经中新经纬、腾讯新闻等转述；2024与2025H1按披露同比反推
A6: 旅游零售 | B6: =C6/(1+F6) | C6: 9.26 | D6: =E6/(1+G6) | E6: 4.77 | F6: 0.2413 | G6: 0.2066 | J6: 同上
A7: 整合营销服务 | B7: =C7/(1+F7) | C7: 8.4 | D7: =E7/(1+G7) | E7: 3.32 | F7: -0.0348 | G7: 0.28 | J7: 同上
A8: 营业总收入 | B8: =C8/(1+F8) | C8: 68.22 | D8: =E8/(1+G8) | E8: 27.99 | F8: 0.0569 | G8: -0.026 | J8: 同上
A9: 其他收入（总收入−三项合计） | B9: =B8-SUM(B5:B7) | C9: =C8-SUM(C5:C7) | D9: =D8-SUM(D5:D7) | E9: =E8-SUM(E5:E7) | J9: 分业务合计与总收入的差额，为未单列的其他收入，非口径矛盾
A10: 众信2026五一 国内游出游人次同比 | C10: 1.68 | J10: 众信旅游《2026年五一出游趋势报告》（2026-04-16，零售数据截至4/16）
A11: 众信2026五一 国内游GMV同比 | C11: 0.38 | J11: 同上。隐含国内游人均成交额 −49%：新增客源来自华中/华北/华东门店（五一出游人次分别+10倍/+9.8倍/+8倍），以短线、目的地参团为主
A12: 全国国内出游人均花费 同比 | B12: -0.057 | C12: -0.032 | J12: 文旅部：2025年出游65.22亿人次(+16.2%)、花费6.30万亿(+9.5%)；2026H1出游34.63亿(+5.4%)、花费3.21万亿(+2.0%)。B=2025全年，C=2026H1
A14: B. 口径假设 | B14: 取值 | J14: 依据
A15: 批发渠道佣金率（同行价→终端成交价） | B15: 0.08 | J15: 出境/国内批发给零售同行的常见返佣约5%–10%，取中值
A16: 7–8月占全年休闲成交额比例 | B16: 0.26 | J16: 2025上半年占全年约44%；暑期为出境与国内（新疆、西北、亲子）共同高峰
A17: 2026年7–8月休闲成交额同比 | B17: -0.04 | J17: 2026H1休闲成交额约−5.8%；暑期出入境航线旅客+约3%、国内游需求稳增，部分对冲
A19: C. 成交额（亿元） | B19: 2024全年 | C19: 2025全年 | D19: 2025 1-8月 | E19: 2026 1-8月 | J19: 说明
A20: 上半年休闲终端成交额 | D20: =D5/(1-$B$15)+D6 | E20: =E5/(1-$B$15)+E6 | J20: 批发÷(1−佣金率)+零售；整合营销（会奖）不属于团队旅游产品，剔除
A21: 7–8月休闲终端成交额 | D21: =C22*$B$16 | E21: =D21*(1+$B$17)
A22: 休闲终端成交额（出境+国内） | B22: =B5/(1-$B$15)+B6 | C22: =C5/(1-$B$15)+C6 | D22: =D20+D21 | E22: =E20+E21
A23: ⭐ 国内团队游占休闲成交额（核心假设） | B23: 0.045 | C23: 0.05 | D23: 0.05 | E23: 0.07 | J23: ⚠ 全表量级取决于这一行。公司从未披露国内游收入或人次（批发主体优耐德/全景为出境批发商）。推法：国内游主要经零售门店与悠哉网销售，按约占零售成交额30%、批发成交额1%估算，合计约5%。2026年上调至7%：五一国内游GMV+38%而同期休闲成交额下滑。访谈拿到真实占比后只需改这一行
A24: 国内团队游成交额 | B24: =B22*B23 | C24: =C22*C23 | D24: =D22*D23 | E24: =E22*E23 | F24: =E24/D24-1 | J24: F列＝2026 1-8月对2025 1-8月；与众信五一国内游GMV+38%对照
A26: D. 九类国内产品假设 | B26: 单均人数（人/单） | C26: 人次占比 2024 | D26: 人次占比 2025 | E26: 人次占比 2026 1-8月 | F26: 人均价 2024（元） | G26: 人均价 2025（元） | H26: 人均价 2026 1-8月（元） | J26: 依据
A27: 含大交通散拼团-大车 | B27: 2.2 | C27: =1-SUM(C28:C35) | D27: =1-SUM(D28:D35) | E27: =1-SUM(E28:E35) | F27: 4700 | G27: 4500 | H27: 4000 | J27: 出发地参团（含机票/高铁）大巴团，众信门店客群主要购买新疆、云南、广西、甘肃、贵州、海南等中长线。占比为残差。2026年均价下调：新开华中/华北门店以高铁可达的中短线为主
A28: 当地拼团多日游-大车 | B28: 2.3 | C28: 0.2 | D28: 0.2 | E28: 0.21 | F28: 2300 | G28: 2200 | H28: 2100 | J28: 目的地参团大巴团；参照同程九寨沟5天4晚2,180元/人
A29: 一日游 | B29: 2.6 | C29: 0.12 | D29: 0.12 | E29: 0.14 | F29: 320 | G29: 300 | H29: 295 | J29: 目的地一日游，标准化低价产品
A30: 含大交通散拼团-小车 | B30: 2.3 | C30: 0.07 | D30: 0.09 | E30: 0.11 | F30: 6800 | G30: 6500 | H30: 6300 | J30: 出发地参团+7座/精品小团（如新疆喀纳斯、伊犁线），团费通常高于大巴团约两成以上
A31: 当地拼团-小车 | B31: 2.4 | C31: 0.06 | D31: 0.08 | E31: 0.1 | F31: 3600 | G31: 3500 | H31: 3400 | J31: 目的地小车拼团，新疆、云南、西北主流形态
A32: 含大交通私家团 | B32: 3.3 | C32: 0.04 | D32: 0.05 | E32: 0.06 | F32: 8000 | G32: 7600 | H32: 7400 | J32: 携程口径：出发地参团私家团人均>5,000元（2020）；叠加中长线与服务升级
A33: 当地私家团 | B33: 3.4 | C33: 0.03 | D33: 0.04 | E33: 0.05 | F33: 3100 | G33: 3000 | H33: 2950 | J33: 携程口径：目的地参团私家团人均2,000–3,000元
A34: 含大交通定制 | B34: 3.2 | C34: 0.02 | D34: 0.025 | E34: 0.035 | F34: 12500 | G34: 12000 | H34: 12000 | J34: 定制游客单价约8,000–12,000元，为跟团游2–3倍
A35: 当地定制 | B35: 3.2 | C35: 0.01 | D35: 0.015 | E35: 0.02 | F35: 6000 | G35: 6000 | H35: 6000 | J35: 目的地包车/管家式定制
A36: 合计（校验=100%） | C36: =SUM(C27:C35) | D36: =SUM(D27:D35) | E36: =SUM(E27:E35)
A38: E. 产出 | B38: 2024全年 | C38: 2025全年 | D38: 2025 1-8月 | E38: 2026 1-8月 | F38: 2026vs2025 1-8月 | J38: 说明
A39: 加权人均价（元/人） | B39: =SUMPRODUCT(C27:C35,F27:F35) | C39: =SUMPRODUCT(D27:D35,G27:G35) | D39: =SUMPRODUCT(D27:D35,G27:G35) | E39: =SUMPRODUCT(E27:E35,H27:H35) | F39: =E39/D39-1 | J39: 与众信五一国内游人均−49%、全国人均花费−3.2%对照：方向一致，幅度取中间
A40: 九类国内产品总收客人次 | B40: =B24*100000000/B39 | C40: =C24*100000000/C39 | D40: =D24*100000000/D39 | E40: =E24*100000000/E39 | F40: =E40/D40-1 | J40: ＝国内团队游成交额÷加权人均价；与众信五一国内游人次+168%对照（节假日快照，全期增速应显著低于此）
A42: 订单均价（元/单）
A43: 含大交通散拼团-大车 | B43: =ROUND(F27*$B27,0) | C43: =ROUND(G27*$B27,0) | D43: =ROUND(G27*$B27,0) | E43: =ROUND(H27*$B27,0) | F43: =E43/D43-1
A44: 当地拼团多日游-大车 | B44: =ROUND(F28*$B28,0) | C44: =ROUND(G28*$B28,0) | D44: =ROUND(G28*$B28,0) | E44: =ROUND(H28*$B28,0) | F44: =E44/D44-1
A45: 一日游 | B45: =ROUND(F29*$B29,0) | C45: =ROUND(G29*$B29,0) | D45: =ROUND(G29*$B29,0) | E45: =ROUND(H29*$B29,0) | F45: =E45/D45-1
A46: 含大交通散拼团-小车 | B46: =ROUND(F30*$B30,0) | C46: =ROUND(G30*$B30,0) | D46: =ROUND(G30*$B30,0) | E46: =ROUND(H30*$B30,0) | F46: =E46/D46-1
...

Sheet 口径说明
A1: 众信旅游（002707.SZ）国内游调研表 · 填写口径与依据
A3: 一、口径
A4: 范围 | B4: 仅众信国内团队游产品。不含出境游、入境接待、会奖（众信博睿）及签证、机票等单项服务。
A5: 含大交通 / 当地 | B5: 含大交通＝出发地参团（含往返机票或高铁）；当地＝目的地参团（游客自行抵达后参团）。大车＝大巴团，小车＝7座等小车拼团。
A6: 订单均价 | B6: 每单终端成交价（元/单）。一单平均2.2–3.4人（拼团约2.3人，私家团/定制约3.3人）。若贵方口径为「人均价」，见第四部分附表。
A7: 波动原因 | B7: 比较口径为2026年1–8月对2025年1–8月；方向词按涨跌幅自动生成（>+3%增长、<−3%下降、其余基本持平）。
A8: 产品名称 | B8: 「当地拼团-小车」（均价行）与「当地拼团多日游-小车」（人次行）按同一类产品处理。
A9: 二、数据性质与可信度
A10: 数据性质 | B10: 众信从未单独披露国内游收入、人次或产品结构，也不披露月度数据。本表以公开财报收入为总盘子，按国内游占比拆出国内部分，再按行业价格带与产品结构推算。
A11: 订单均价 | B11: 中等可信：锚定国内跟团游公开价格带（目的地大巴团约2,000–2,300元/人，携程私家团人均>3,500元，定制8,000–12,000元）。
A12: 收客人次 | B12: 较低可信。全部人次的量级取决于一个假设——国内团队游占众信休闲成交额的比例（2025年取5%、2026年1–8月取7%）。该比例公司从未披露，是全表最大的不确定来源；访谈拿到真实比例后，可据此对全表人次整体重算。
A13: 交叉验证 | B13: ="众信2026五一：国内游出游人次+168%、GMV+38%（隐含人均−49%）。本表2026年1–8月人次"&TEXT('测算底稿'!F40,"+0%;-0%")&"、成交额"&TEXT('测算底稿'!F24,"+0%;-0%")&"、人均"&TEXT('测算底稿'!F39,"+0%;-0%")&"，方向一致；全期增速低于节假日快照，符合预期。"
A15: 三、公开锚点
A16: 项目 | B16: 2024全年 | C16: 2025全年 | D16: 2025上半年 | E16: 2026上半年 | F16: 来源
A17: 众信 旅游批发（亿元） | B17: ='测算底稿'!B5 | C17: ='测算底稿'!C5 | D17: ='测算底稿'!D5 | E17: ='测算底稿'!E5 | F17: 2025年报、2026中报（经中新经纬、腾讯新闻等转述）；2024与2025上半年按披露同比反推
A18: 众信 旅游零售（亿元） | B18: ='测算底稿'!B6 | C18: ='测算底稿'!C6 | D18: ='测算底稿'!D6 | E18: ='测算底稿'!E6 | F18: 同上
A19: 众信 整合营销服务（亿元） | B19: ='测算底稿'!B7 | C19: ='测算底稿'!C7 | D19: ='测算底稿'!D7 | E19: ='测算底稿'!E7 | F19: 同上
A20: 众信 营业总收入（亿元） | B20: ='测算底稿'!B8 | C20: ='测算底稿'!C8 | D20: ='测算底稿'!D8 | E20: ='测算底稿'!E8 | F20: 同上
A21: 众信 其他收入（亿元） | B21: ='测算底稿'!B9 | C21: ='测算底稿'!C9 | D21: ='测算底稿'!D9 | E21: ='测算底稿'!E9 | F21: 分业务合计与总收入的差额，为未单列的其他收入
A22: 全国国内出游人次 | B22: 2024 56.15亿｜2025 65.22亿(+16.2%)｜2026H1 34.63亿(+5.4%) | F22: 文化和旅游部（2026-01-26、2026-08-07发布）
A23: 全国国内出游花费 | B23: 2024 5.75万亿｜2025 6.30万亿(+9.5%)｜2026H1 3.21万亿(+2.0%) | F23: 同上；人均花费2025−5.7%、2026H1−3.2%
A24: 众信2026五一 国内游 | B24: 出游人次+168%，GMV+38%；新疆、广东、云南领跑 | F24: 众信旅游《2026年五一出游趋势报告》（2026-04-16）
A25: 众信2025五一 国内热门 | B25: 广西、甘肃、云南、贵州、海南 | F25: 众信旅游集团五一出游趋势报告（2025-04）
A27: 四、附表：人均价（元/人）
A28: 产品 | B28: 2024全年 | C28: 2025全年 | D28: 2025 1-8月 | E28: 2026 1-8月 | F28: 单均人数（人/单）
A29: 含大交通散拼团-大车 | B29: ='测算底稿'!F27 | C29: ='测算底稿'!G27 | D29: ='测算底稿'!G27 | E29: ='测算底稿'!H27 | F29: ='测算底稿'!B27
A30: 当地拼团多日游-大车 | B30: ='测算底稿'!F28 | C30: ='测算底稿'!G28 | D30: ='测算底稿'!G28 | E30: ='测算底稿'!H28 | F30: ='测算底稿'!B28
A31: 一日游 | B31: ='测算底稿'!F29 | C31: ='测算底稿'!G29 | D31: ='测算底稿'!G29 | E31: ='测算底稿'!H29 | F31: ='测算底稿'!B29
A32: 含大交通散拼团-小车 | B32: ='测算底稿'!F30 | C32: ='测算底稿'!G30 | D32: ='测算底稿'!G30 | E32: ='测算底稿'!H30 | F32: ='测算底稿'!B30
A33: 当地拼团-小车 | B33: ='测算底稿'!F31 | C33: ='测算底稿'!G31 | D33: ='测算底稿'!G31 | E33: ='测算底稿'!H31 | F33: ='测算底稿'!B31
A34: 含大交通私家团 | B34: ='测算底稿'!F32 | C34: ='测算底稿'!G32 | D34: ='测算底稿'!G32 | E34: ='测算底稿'!H32 | F34: ='测算底稿'!B32
A35: 当地私家团 | B35: ='测算底稿'!F33 | C35: ='测算底稿'!G33 | D35: ='测算底稿'!G33 | E35: ='测算底稿'!H33 | F35: ='测算底稿'!B33
A36: 含大交通定制 | B36: ='测算底稿'!F34 | C36: ='测算底稿'!G34 | D36: ='测算底稿'!G34 | E36: ='测算底稿'!H34 | F36: ='测算底稿'!B34
A37: 当地定制 | B37: ='测算底稿'!F35 | C37: ='测算底稿'!G35 | D37: ='测算底稿'!G35 | E37: ='测算底稿'!H35 | F37: ='测算底稿'!B35
A39: 五、关键假设
A40: 国内游占休闲成交额 2025 | B40: ='测算底稿'!C23 | C40: 公司未披露；按零售成交额约30%、批发约1%估算
A41: 国内游占休闲成交额 2026年1–8月 | B41: ='测算底稿'!E23 | C41: 五一国内游GMV+38%而同期休闲成交额下滑，占比上调
A42: 批发渠道佣金率 | B42: ='测算底稿'!B15 | C42: 批发收入为同行价，按此还原终端成交价
A43: 7–8月占全年成交额 | B43: ='测算底稿'!B16 | C43: 暑期出境与国内共同高峰
A44: 2026年7–8月休闲成交额同比 | B44: ='测算底稿'!B17 | C44: 2026上半年约−5.8%，暑期需求部分对冲
...
